Workbook
Name Claim_Total: Table1[Claim Total]
Name Claim_Total: Table1[Claim Total]
Name CurrentDeductible: Table1[Paid Deductible (Current)]
Name CurrentDeductible: Table1[Paid Deductible (Current)]
Name Fire: 'Drop downs'!$E$3:$E$11
Name HigherDeductible: Table1[Paid Deductible (Other)]
Name HigherDeductible: Table1[Paid Deductible (Other)]
Name LossClassification: 'Drop downs'!$D$2:$D$6
Name LowerDeductible: Table1[Paid Deductible (Current)]
Name LowerDeductible: Table1[Paid Deductible (Current)]
Name Negligent_Maintenance: 'Drop downs'!$F$4:$F$11
Name OtherDeductible: Table1[Paid Deductible (Other)]
Name OtherDeductible: Table1[Paid Deductible (Other)]
Name OwnershipStatus: Table1[Ownership Status]
Name OwnershipStatus: Table1[Ownership Status]
Name PaidClaim: Table1[Paid Total]
Name PaidClaim: Table1[Paid Total]
Name PolicyYears: Table1[Policy Period]
Name PolicyYears: Table1[Policy Period]
Name Reserve: Table1[Reserve Total]
Name Reserve: Table1[Reserve Total]
Name Shooting: 'Drop downs'!$E$3:$E$11
Name Slicer_Policy_Period: #N/A
Name Slicer_Status: #N/A
Name Slip_Fall: 'Drop downs'!#REF!
Name Status: Table1[[Status ]]
Name Status: Table1[[Status ]]
Name WaterDamage: 'Drop downs'!#REF!
Name Windstorm: 'Drop downs'!$F$4:$F$11

Sheet Loss Run Summary
F3: Enter Claim Total for that Policy Year
A4: Carrier | B4: Location(s) | C4: Layer | D4: Loss Run Ownership | E4: Valulation Date | F4: 2010 - 2011 | G4: 2011 - 2012 | H4: 2012 - 2013 | I4: 2013 - 2014 | J4: 2014 - 2015 | K4: 2015 - 2016 | L4: 2016 - 2017 | M4: 2017 - 2018 | N4: 2018 - 2019 | O4: 2019 - 2020 | P4: 2020 - 2021 | Q4: 2021 - 2022 | R4: 2022 - 2023 | S4: 2023 - 2024
A22: Total | F22: =SUM(F5:F21) -> 0 | G22: =SUM(G5:G21) -> 0 | H22: =SUM(H5:H21) -> 0 | I22: =SUM(I5:I21) -> 0 | J22: =SUM(J5:J21) -> 0 | K22: =SUM(K5:K21) -> 0 | L22: =SUM(L5:L21) -> 0 | M22: =SUM(M5:M21) -> 0 | ... S22: =SUM(S5:S21) -> 0

Sheet Claim Details
S1: Deductibles
T7: Loss Classification | U7: Alternative Deductible 1 | W7: Alternative Deductible 2
T8: AOP | U8: 100000 | W8: 250000
T9: Windstorm | U9: 0.01 | W9: 0.01
T10: Named Windstorm | U10: 0.03 | W10: 0.03
M15: Totals | N15: =SUBTOTAL(9,N17:N10022) -> 0 | O15: =SUBTOTAL(9,O17:O10022) -> 0 | P15: =SUBTOTAL(9,P17:P10022) -> 0 | Q15: =SUBTOTAL(9,Q17:Q10022) -> 0 | S15: Current Deductibles | V15: Other Deductibles
A16: Policy Period | B16: Current Ownership Or Prior Ownership Loss Run | C16: Carrier | D16: Claim Number | E16: Date of Loss | F16: Loss Location | G16: City | H16: State | I16: Ownership Status | J16: Loss Description | K16: Loss Classification | L16: Loss Sub-Classification | M16: LR Valuation Date | N16: DBB Claim Total | O16: Paid Total | P16: Reserve Total | Q16: Claim Total | R16: Status | S16: Policy Deductible(Current) | T16: TIV (if % Deductible) | U16: Paid Deductible (Current) | V16: Policy Deductible (Other) | W16: Paid Deductible (Other)
Q17: =SUM(Table1[[#This Row],[DBB Claim Total]:[Reserve Total]]) -> 0 | S17: =IF(K17=$T$9,$U$9,IF(K17=$T$10,$U$10,IF(K17=$T$11,$U$11,IF(K17=$T$12,$U$12,$U$8)))) -> 0 | U17: =IF(Q17<(IF(ISBLANK(T17),S17,S17*T17)),0,Q17-(IF(ISBLANK(T17),S17,S17*T17))) -> 0 | V17: =IF(K17=$T$9,$W$9,IF(K17=$T$10,$W$10,IF(K17=$T$11,$W$11,IF(K17=$T$12,$W$12,$W$8)))) -> 0 | W17: =IF(Q17<(IF(ISBLANK(T17),V17,V17*T17)),0,Q17-(IF(ISBLANK(T17),V17,V17*T17))) -> 0
Q18: =SUM(Table1[[#This Row],[DBB Claim Total]:[Reserve Total]]) -> 0 | S18: =IF(K18=$T$9,$U$9,IF(K18=$T$10,$U$10,IF(K18=$T$11,$U$11,IF(K18=$T$12,$U$12,$U$8)))) -> 0 | U18: =IF(Q18<(IF(ISBLANK(T18),S18,S18*T18)),0,Q18-(IF(ISBLANK(T18),S18,S18*T18))) -> 0 | V18: =IF(K18=$T$9,$W$9,IF(K18=$T$10,$W$10,IF(K18=$T$11,$W$11,IF(K18=$T$12,$W$12,$W$8)))) -> 0 | W18: =IF(Q18<(IF(ISBLANK(T18),V18,V18*T18)),0,Q18-(IF(ISBLANK(T18),V18,V18*T18))) -> 0
Q19: =SUM(Table1[[#This Row],[DBB Claim Total]:[Reserve Total]]) -> 0 | S19: =IF(K19=$T$9,$U$9,IF(K19=$T$10,$U$10,IF(K19=$T$11,$U$11,IF(K19=$T$12,$U$12,$U$8)))) -> 0 | U19: =IF(Q19<(IF(ISBLANK(T19),S19,S19*T19)),0,Q19-(IF(ISBLANK(T19),S19,S19*T19))) -> 0 | V19: =IF(K19=$T$9,$W$9,IF(K19=$T$10,$W$10,IF(K19=$T$11,$W$11,IF(K19=$T$12,$W$12,$W$8)))) -> 0 | W19: =IF(Q19<(IF(ISBLANK(T19),V19,V19*T19)),0,Q19-(IF(ISBLANK(T19),V19,V19*T19))) -> 0
Q20: =SUM(Table1[[#This Row],[DBB Claim Total]:[Reserve Total]]) -> 0 | S20: =IF(K20=$T$9,$U$9,IF(K20=$T$10,$U$10,IF(K20=$T$11,$U$11,IF(K20=$T$12,$U$12,$U$8)))) -> 0 | U20: =IF(Q20<(IF(ISBLANK(T20),S20,S20*T20)),0,Q20-(IF(ISBLANK(T20),S20,S20*T20))) -> 0 | V20: =IF(K20=$T$9,$W$9,IF(K20=$T$10,$W$10,IF(K20=$T$11,$W$11,IF(K20=$T$12,$W$12,$W$8)))) -> 0 | W20: =IF(Q20<(IF(ISBLANK(T20),V20,V20*T20)),0,Q20-(IF(ISBLANK(T20),V20,V20*T20))) -> 0
Q21: =SUM(Table1[[#This Row],[DBB Claim Total]:[Reserve Total]]) -> 0 | S21: =IF(K21=$T$9,$U$9,IF(K21=$T$10,$U$10,IF(K21=$T$11,$U$11,IF(K21=$T$12,$U$12,$U$8)))) -> 0 | U21: =IF(Q21<(IF(ISBLANK(T21),S21,S21*T21)),0,Q21-(IF(ISBLANK(T21),S21,S21*T21))) -> 0 | V21: =IF(K21=$T$9,$W$9,IF(K21=$T$10,$W$10,IF(K21=$T$11,$W$11,IF(K21=$T$12,$W$12,$W$8)))) -> 0 | W21: =IF(Q21<(IF(ISBLANK(T21),V21,V21*T21)),0,Q21-(IF(ISBLANK(T21),V21,V21*T21))) -> 0
Q22: =SUM(Table1[[#This Row],[DBB Claim Total]:[Reserve Total]]) -> 0 | S22: =IF(K22=$T$9,$U$9,IF(K22=$T$10,$U$10,IF(K22=$T$11,$U$11,IF(K22=$T$12,$U$12,$U$8)))) -> 0 | U22: =IF(Q22<(IF(ISBLANK(T22),S22,S22*T22)),0,Q22-(IF(ISBLANK(T22),S22,S22*T22))) -> 0 | V22: =IF(K22=$T$9,$W$9,IF(K22=$T$10,$W$10,IF(K22=$T$11,$W$11,IF(K22=$T$12,$W$12,$W$8)))) -> 0 | W22: =IF(Q22<(IF(ISBLANK(T22),V22,V22*T22)),0,Q22-(IF(ISBLANK(T22),V22,V22*T22))) -> 0
Q23: =SUM(Table1[[#This Row],[DBB Claim Total]:[Reserve Total]]) -> 0 | S23: =IF(K23=$T$9,$U$9,IF(K23=$T$10,$U$10,IF(K23=$T$11,$U$11,IF(K23=$T$12,$U$12,$U$8)))) -> 0 | U23: =IF(Q23<(IF(ISBLANK(T23),S23,S23*T23)),0,Q23-(IF(ISBLANK(T23),S23,S23*T23))) -> 0 | V23: =IF(K23=$T$9,$W$9,IF(K23=$T$10,$W$10,IF(K23=$T$11,$W$11,IF(K23=$T$12,$W$12,$W$8)))) -> 0 | W23: =IF(Q23<(IF(ISBLANK(T23),V23,V23*T23)),0,Q23-(IF(ISBLANK(T23),V23,V23*T23))) -> 0
Q24: =SUM(Table1[[#This Row],[DBB Claim Total]:[Reserve Total]]) -> 0 | S24: =IF(K24=$T$9,$U$9,IF(K24=$T$10,$U$10,IF(K24=$T$11,$U$11,IF(K24=$T$12,$U$12,$U$8)))) -> 0 | U24: =IF(Q24<(IF(ISBLANK(T24),S24,S24*T24)),0,Q24-(IF(ISBLANK(T24),S24,S24*T24))) -> 0 | V24: =IF(K24=$T$9,$W$9,IF(K24=$T$10,$W$10,IF(K24=$T$11,$W$11,IF(K24=$T$12,$W$12,$W$8)))) -> 0 | W24: =IF(Q24<(IF(ISBLANK(T24),V24,V24*T24)),0,Q24-(IF(ISBLANK(T24),V24,V24*T24))) -> 0
Q25: =SUM(Table1[[#This Row],[DBB Claim Total]:[Reserve Total]]) -> 0 | S25: =IF(K25=$T$9,$U$9,IF(K25=$T$10,$U$10,IF(K25=$T$11,$U$11,IF(K25=$T$12,$U$12,$U$8)))) -> 0 | U25: =IF(Q25<(IF(ISBLANK(T25),S25,S25*T25)),0,Q25-(IF(ISBLANK(T25),S25,S25*T25))) -> 0 | V25: =IF(K25=$T$9,$W$9,IF(K25=$T$10,$W$10,IF(K25=$T$11,$W$11,IF(K25=$T$12,$W$12,$W$8)))) -> 0 | W25: =IF(Q25<(IF(ISBLANK(T25),V25,V25*T25)),0,Q25-(IF(ISBLANK(T25),V25,V25*T25))) -> 0
Q26: =SUM(Table1[[#This Row],[DBB Claim Total]:[Reserve Total]]) -> 0 | S26: =IF(K26=$T$9,$U$9,IF(K26=$T$10,$U$10,IF(K26=$T$11,$U$11,IF(K26=$T$12,$U$12,$U$8)))) -> 0 | U26: =IF(Q26<(IF(ISBLANK(T26),S26,S26*T26)),0,Q26-(IF(ISBLANK(T26),S26,S26*T26))) -> 0 | V26: =IF(K26=$T$9,$W$9,IF(K26=$T$10,$W$10,IF(K26=$T$11,$W$11,IF(K26=$T$12,$W$12,$W$8)))) -> 0 | W26: =IF(Q26<(IF(ISBLANK(T26),V26,V26*T26)),0,Q26-(IF(ISBLANK(T26),V26,V26*T26))) -> 0
Q27: =SUM(Table1[[#This Row],[DBB Claim Total]:[Reserve Total]]) -> 0 | S27: =IF(K27=$T$9,$U$9,IF(K27=$T$10,$U$10,IF(K27=$T$11,$U$11,IF(K27=$T$12,$U$12,$U$8)))) -> 0 | U27: =IF(Q27<(IF(ISBLANK(T27),S27,S27*T27)),0,Q27-(IF(ISBLANK(T27),S27,S27*T27))) -> 0 | V27: =IF(K27=$T$9,$W$9,IF(K27=$T$10,$W$10,IF(K27=$T$11,$W$11,IF(K27=$T$12,$W$12,$W$8)))) -> 0 | W27: =IF(Q27<(IF(ISBLANK(T27),V27,V27*T27)),0,Q27-(IF(ISBLANK(T27),V27,V27*T27))) -> 0
Q28: =SUM(Table1[[#This Row],[DBB Claim Total]:[Reserve Total]]) -> 0 | S28: =IF(K28=$T$9,$U$9,IF(K28=$T$10,$U$10,IF(K28=$T$11,$U$11,IF(K28=$T$12,$U$12,$U$8)))) -> 0 | U28: =IF(Q28<(IF(ISBLANK(T28),S28,S28*T28)),0,Q28-(IF(ISBLANK(T28),S28,S28*T28))) -> 0 | V28: =IF(K28=$T$9,$W$9,IF(K28=$T$10,$W$10,IF(K28=$T$11,$W$11,IF(K28=$T$12,$W$12,$W$8)))) -> 0 | W28: =IF(Q28<(IF(ISBLANK(T28),V28,V28*T28)),0,Q28-(IF(ISBLANK(T28),V28,V28*T28))) -> 0
... Q114: =SUM(Table1[[#This Row],[DBB Claim Total]:[Reserve Total]]) -> 0 | S114: =IF(K114=$T$9,$U$9,IF(K114=$T$10,$U$10,IF(K114=$T$11,$U$11,IF(K114=$T$12,$U$12,$U$8)))) -> 0 | U114: =IF(Q114<(IF(ISBLANK(T114),S114,S114*T114)),0,Q114-(IF(ISBLANK(T114),S114,S114*T114))) -> 0 | V114: =IF(K114=$T$9,$W$9,IF(K114=$T$10,$W$10,IF(K114=$T$11,$W$11,IF(K114=$T$12,$W$12,$W$8)))) -> 0 | W114: =IF(Q114<(IF(ISBLANK(T114),V114,V114*T114)),0,Q114-(IF(ISBLANK(T114),V114,V114*T114))) -> 0
Q115: =SUM(N115:P115) -> 0 | S115: =IF(K115=$T$9,$U$9,IF(K115=$T$10,$U$10,IF(K115=$T$11,$U$11,IF(K115=$T$12,$U$12,$U$8)))) -> 0 | U115: =IF(Q115<(IF(ISBLANK(T115),S115,S115*T115)),0,Q115-(IF(ISBLANK(T115),S115,S115*T115))) -> 0 | V115: =IF(K115=$T$9,$W$9,IF(K115=$T$10,$W$10,IF(K115=$T$11,$W$11,IF(K115=$T$12,$W$12,$W$8)))) -> 0 | W115: =IF(Q115<(IF(ISBLANK(T115),V115,V115*T115)),0,Q115-(IF(ISBLANK(T115),V115,V115*T115))) -> 0
Q116: =SUM(N116:P116) -> 0 | S116: =IF(K116=$T$9,$U$9,IF(K116=$T$10,$U$10,IF(K116=$T$11,$U$11,IF(K116=$T$12,$U$12,$U$8)))) -> 0 | U116: =IF(Q116<(IF(ISBLANK(T116),S116,S116*T116)),0,Q116-(IF(ISBLANK(T116),S116,S116*T116))) -> 0 | V116: =IF(K116=$T$9,$W$9,IF(K116=$T$10,$W$10,IF(K116=$T$11,$W$11,IF(K116=$T$12,$W$12,$W$8)))) -> 0 | W116: =IF(Q116<(IF(ISBLANK(T116),V116,V116*T116)),0,Q116-(IF(ISBLANK(T116),V116,V116*T116))) -> 0
Q117: =SUM(N117:P117) -> 0 | S117: =IF(K117=$T$9,$U$9,IF(K117=$T$10,$U$10,IF(K117=$T$11,$U$11,IF(K117=$T$12,$U$12,$U$8)))) -> 0 | U117: =IF(Q117<(IF(ISBLANK(T117),S117,S117*T117)),0,Q117-(IF(ISBLANK(T117),S117,S117*T117))) -> 0 | V117: =IF(K117=$T$9,$W$9,IF(K117=$T$10,$W$10,IF(K117=$T$11,$W$11,IF(K117=$T$12,$W$12,$W$8)))) -> 0 | W117: =IF(Q117<(IF(ISBLANK(T117),V117,V117*T117)),0,Q117-(IF(ISBLANK(T117),V117,V117*T117))) -> 0
Q118: =SUM(N118:P118) -> 0 | S118: =IF(K118=$T$9,$U$9,IF(K118=$T$10,$U$10,IF(K118=$T$11,$U$11,IF(K118=$T$12,$U$12,$U$8)))) -> 0 | U118: =IF(Q118<(IF(ISBLANK(T118),S118,S118*T118)),0,Q118-(IF(ISBLANK(T118),S118,S118*T118))) -> 0 | V118: =IF(K118=$T$9,$W$9,IF(K118=$T$10,$W$10,IF(K118=$T$11,$W$11,IF(K118=$T$12,$W$12,$W$8)))) -> 0 | W118: =IF(Q118<(IF(ISBLANK(T118),V118,V118*T118)),0,Q118-(IF(ISBLANK(T118),V118,V118*T118))) -> 0
Q119: =SUM(N119:P119) -> 0 | S119: =IF(K119=$T$9,$U$9,IF(K119=$T$10,$U$10,IF(K119=$T$11,$U$11,IF(K119=$T$12,$U$12,$U$8)))) -> 0 | U119: =IF(Q119<(IF(ISBLANK(T119),S119,S119*T119)),0,Q119-(IF(ISBLANK(T119),S119,S119*T119))) -> 0 | V119: =IF(K119=$T$9,$W$9,IF(K119=$T$10,$W$10,IF(K119=$T$11,$W$11,IF(K119=$T$12,$W$12,$W$8)))) -> 0 | W119: =IF(Q119<(IF(ISBLANK(T119),V119,V119*T119)),0,Q119-(IF(ISBLANK(T119),V119,V119*T119))) -> 0
Q120: =SUM(N120:P120) -> 0 | S120: =IF(K120=$T$9,$U$9,IF(K120=$T$10,$U$10,IF(K120=$T$11,$U$11,IF(K120=$T$12,$U$12,$U$8)))) -> 0 | U120: =IF(Q120<(IF(ISBLANK(T120),S120,S120*T120)),0,Q120-(IF(ISBLANK(T120),S120,S120*T120))) -> 0 | V120: =IF(K120=$T$9,$W$9,IF(K120=$T$10,$W$10,IF(K120=$T$11,$W$11,IF(K120=$T$12,$W$12,$W$8)))) -> 0 | W120: =IF(Q120<(IF(ISBLANK(T120),V120,V120*T120)),0,Q120-(IF(ISBLANK(T120),V120,V120*T120))) -> 0
Q121: =SUM(N121:P121) -> 0 | S121: =IF(K121=$T$9,$U$9,IF(K121=$T$10,$U$10,IF(K121=$T$11,$U$11,IF(K121=$T$12,$U$12,$U$8)))) -> 0 | U121: =IF(Q121<(IF(ISBLANK(T121),S121,S121*T121)),0,Q121-(IF(ISBLANK(T121),S121,S121*T121))) -> 0 | V121: =IF(K121=$T$9,$W$9,IF(K121=$T$10,$W$10,IF(K121=$T$11,$W$11,IF(K121=$T$12,$W$12,$W$8)))) -> 0 | W121: =IF(Q121<(IF(ISBLANK(T121),V121,V121*T121)),0,Q121-(IF(ISBLANK(T121),V121,V121*T121))) -> 0
Q122: =SUM(N122:P122) -> 0 | S122: =IF(K122=$T$9,$U$9,IF(K122=$T$10,$U$10,IF(K122=$T$11,$U$11,IF(K122=$T$12,$U$12,$U$8)))) -> 0 | U122: =IF(Q122<(IF(ISBLANK(T122),S122,S122*T122)),0,Q122-(IF(ISBLANK(T122),S122,S122*T122))) -> 0 | V122: =IF(K122=$T$9,$W$9,IF(K122=$T$10,$W$10,IF(K122=$T$11,$W$11,IF(K122=$T$12,$W$12,$W$8)))) -> 0 | W122: =IF(Q122<(IF(ISBLANK(T122),V122,V122*T122)),0,Q122-(IF(ISBLANK(T122),V122,V122*T122))) -> 0
Q123: =SUM(N123:P123) -> 0 | S123: =IF(K123=$T$9,$U$9,IF(K123=$T$10,$U$10,IF(K123=$T$11,$U$11,IF(K123=$T$12,$U$12,$U$8)))) -> 0 | U123: =IF(Q123<(IF(ISBLANK(T123),S123,S123*T123)),0,Q123-(IF(ISBLANK(T123),S123,S123*T123))) -> 0 | V123: =IF(K123=$T$9,$W$9,IF(K123=$T$10,$W$10,IF(K123=$T$11,$W$11,IF(K123=$T$12,$W$12,$W$8)))) -> 0 | W123: =IF(Q123<(IF(ISBLANK(T123),V123,V123*T123)),0,Q123-(IF(ISBLANK(T123),V123,V123*T123))) -> 0
Q124: =SUM(N124:P124) -> 0 | S124: =IF(K124=$T$9,$U$9,IF(K124=$T$10,$U$10,IF(K124=$T$11,$U$11,IF(K124=$T$12,$U$12,$U$8)))) -> 0 | U124: =IF(Q124<(IF(ISBLANK(T124),S124,S124*T124)),0,Q124-(IF(ISBLANK(T124),S124,S124*T124))) -> 0 | V124: =IF(K124=$T$9,$W$9,IF(K124=$T$10,$W$10,IF(K124=$T$11,$W$11,IF(K124=$T$12,$W$12,$W$8)))) -> 0 | W124: =IF(Q124<(IF(ISBLANK(T124),V124,V124*T124)),0,Q124-(IF(ISBLANK(T124),V124,V124*T124))) -> 0
Q125: =SUM(N125:P125) -> 0 | S125: =IF(K125=$T$9,$U$9,IF(K125=$T$10,$U$10,IF(K125=$T$11,$U$11,IF(K125=$T$12,$U$12,$U$8)))) -> 0 | U125: =IF(Q125<(IF(ISBLANK(T125),S125,S125*T125)),0,Q125-(IF(ISBLANK(T125),S125,S125*T125))) -> 0 | V125: =IF(K125=$T$9,$W$9,IF(K125=$T$10,$W$10,IF(K125=$T$11,$W$11,IF(K125=$T$12,$W$12,$W$8)))) -> 0 | W125: =IF(Q125<(IF(ISBLANK(T125),V125,V125*T125)),0,Q125-(IF(ISBLANK(T125),V125,V125*T125))) -> 0
Q126: =SUM(N126:P126) -> 0 | S126: =IF(K126=$T$9,$U$9,IF(K126=$T$10,$U$10,IF(K126=$T$11,$U$11,IF(K126=$T$12,$U$12,$U$8)))) -> 0 | U126: =IF(Q126<(IF(ISBLANK(T126),S126,S126*T126)),0,Q126-(IF(ISBLANK(T126),S126,S126*T126))) -> 0 | V126: =IF(K126=$T$9,$W$9,IF(K126=$T$10,$W$10,IF(K126=$T$11,$W$11,IF(K126=$T$12,$W$12,$W$8)))) -> 0 | W126: =IF(Q126<(IF(ISBLANK(T126),V126,V126*T126)),0,Q126-(IF(ISBLANK(T126),V126,V126*T126))) -> 0
... Q140: =SUM(N140:P140) -> 0 | S140: =IF(K140=$T$9,$U$9,IF(K140=$T$10,$U$10,IF(K140=$T$11,$U$11,IF(K140=$T$12,$U$12,$U$8)))) -> 0 | U140: =IF(Q140<(IF(ISBLANK(T140),S140,S140*T140)),0,Q140-(IF(ISBLANK(T140),S140,S140*T140))) -> 0 | V140: =IF(K140=$T$9,$W$9,IF(K140=$T$10,$W$10,IF(K140=$T$11,$W$11,IF(K140=$T$12,$W$12,$W$8)))) -> 0 | W140: =IF(Q140<(IF(ISBLANK(T140),V140,V140*T140)),0,Q140-(IF(ISBLANK(T140),V140,V140*T140))) -> 0

Sheet Loss Summary Analysis
A2: Property Loss Summary
D4: ='Claim Details'!T7 -> Loss Classification | E4: Proposed Deductible | G4: Alternative Deductible
D5: ='Claim Details'!T8 -> AOP | E5: ='Claim Details'!U8 -> 100000 | G5: ='Claim Details'!W8 -> 250000
D6: =IF('Claim Details'!T9=0,"",'Claim Details'!T9) -> Windstorm | E6: ='Claim Details'!U9 -> 0.01 | G6: ='Claim Details'!W9 -> 0.01
D7: =IF('Claim Details'!T10=0,"",'Claim Details'!T10) -> Named Windstorm | E7: ='Claim Details'!U10 -> 0.03 | G7: ='Claim Details'!W10 -> 0.03
C10: Gross Loss | E10: Excess of Proposed Deductible | G10: Excess of Alternative Deductible
A11: All Locations in Loss Runs (Owned & Sold) | B11: Policy Year | C11: # of Claims | D11: Total | E11: # of Claims | F11: Claim Total | G11: # of Claims | H11: Claim Total
B12: 2019 - 2020 | C12: =COUNTIF('Claim Details'!$A$17:$A$506,B12) -> 0 | D12: =SUMIF(PolicyYears,B12,Claim_Total) -> 0 | E12: =COUNTIFS(PolicyYears,B12,CurrentDeductible,">0") -> 0 | F12: =SUMIF(PolicyYears,B12,CurrentDeductible) -> 0 | G12: =COUNTIFS(PolicyYears,B12,OtherDeductible,">0") -> 0 | H12: =SUMIF(PolicyYears,B12,OtherDeductible) -> 0
B13: 2020 - 2021 | C13: =COUNTIF('Claim Details'!$A$17:$A$506,B13) -> 0 | D13: =SUMIF(PolicyYears,B13,Claim_Total) -> 0 | E13: =COUNTIFS(PolicyYears,B13,CurrentDeductible,">0") -> 0 | F13: =SUMIF(PolicyYears,B13,CurrentDeductible) -> 0 | G13: =COUNTIFS(PolicyYears,B13,OtherDeductible,">0") -> 0 | H13: =SUMIF(PolicyYears,B13,OtherDeductible) -> 0
B14: 2021 - 2022 | C14: =COUNTIF('Claim Details'!$A$17:$A$506,B14) -> 0 | D14: =SUMIF(PolicyYears,B14,Claim_Total) -> 0 | E14: =COUNTIFS(PolicyYears,B14,CurrentDeductible,">0") -> 0 | F14: =SUMIF(PolicyYears,B14,CurrentDeductible) -> 0 | G14: =COUNTIFS(PolicyYears,B14,OtherDeductible,">0") -> 0 | H14: =SUMIF(PolicyYears,B14,OtherDeductible) -> 0
B15: 2022 - 2023 | C15: =COUNTIF('Claim Details'!$A$17:$A$506,B15) -> 0 | D15: =SUMIF(PolicyYears,B15,Claim_Total) -> 0 | E15: =COUNTIFS(PolicyYears,B15,CurrentDeductible,">0") -> 0 | F15: =SUMIF(PolicyYears,B15,CurrentDeductible) -> 0 | G15: =COUNTIFS(PolicyYears,B15,OtherDeductible,">0") -> 0 | H15: =SUMIF(PolicyYears,B15,OtherDeductible) -> 0
B16: 2023 - 2024 | C16: =COUNTIF('Claim Details'!$A$17:$A$506,B16) -> 0 | D16: =SUMIF(PolicyYears,B16,Claim_Total) -> 0 | E16: =COUNTIFS(PolicyYears,B16,CurrentDeductible,">0") -> 0 | F16: =SUMIF(PolicyYears,B16,CurrentDeductible) -> 0 | G16: =COUNTIFS(PolicyYears,B16,OtherDeductible,">0") -> 0 | H16: =SUMIF(PolicyYears,B16,OtherDeductible) -> 0
B17: 2024 - 2025 | C17: =COUNTIF('Claim Details'!$A$17:$A$506,B17) -> 0 | D17: =SUMIF(PolicyYears,B17,Claim_Total) -> 0 | E17: =COUNTIFS(PolicyYears,B17,CurrentDeductible,">0") -> 0 | F17: =SUMIF(PolicyYears,B17,CurrentDeductible) -> 0 | G17: =COUNTIFS(PolicyYears,B17,OtherDeductible,">0") -> 0 | H17: =SUMIF(PolicyYears,B17,OtherDeductible) -> 0
B18: Grand Total | C18: =SUM(C12:C17) -> 0 | D18: =SUM(D12:D17) -> 0 | E18: =SUM(E12:E17) -> 0 | F18: =SUM(F12:F17) -> 0 | G18: =SUM(G12:G17) -> 0 | H18: =SUM(H12:H17) -> 0
B19: =COUNTIF(B12:B17,"*")&"-year AAL" -> 6-year AAL | C19: =C18/COUNTIF($B$12:$B$17,"*") -> 0 | D19: =D18/COUNTIF($B$12:$B$17,"*") -> 0 | E19: =E18/COUNTIF($B$12:$B$17,"*") -> 0 | F19: =F18/COUNTIF($B$12:$B$17,"*") -> 0 | G19: =G18/COUNTIF($B$12:$B$17,"*") -> 0 | H19: =H18/COUNTIF($B$12:$B$17,"*") -> 0
B20: ='Drop downs'!G2&"-year AAL" -> 3-year AAL | C20: =AVERAGE(OFFSET(C11,COUNT(C12:C17),0,-'Drop downs'!$G$2)) -> 0 | D20: =AVERAGE(OFFSET(D11,COUNT(D12:D17),0,-'Drop downs'!$G$2)) -> 0 | E20: =AVERAGE(OFFSET(E11,COUNT(E12:E17),0,-'Drop downs'!$G$2)) -> 0 | F20: =AVERAGE(OFFSET(F11,COUNT(F12:F17),0,-'Drop downs'!$G$2)) -> 0 | G20: =AVERAGE(OFFSET(G11,COUNT(G12:G17),0,-'Drop downs'!$G$2)) -> 0 | H20: =AVERAGE(OFFSET(H11,COUNT(H12:H17),0,-'Drop downs'!$G$2)) -> 0
C23: Gross Loss | E23: Excess of Proposed Deductible | G23: Excess of Alternative Deductible
A24: Currently Owned Locations Only | B24: Policy Year | C24: # of Claims | D24: Total | E24: # of Claims | F24: Claim Total | G24: # of Claims | H24: Claim Total
B25: 2018 - 2019 | C25: =COUNTIFS(OwnershipStatus,'Drop downs'!$B$3,PolicyYears,B25) -> 0 | D25: =SUMIFS(Claim_Total,PolicyYears,B25,OwnershipStatus,'Drop downs'!$B$3) -> 0 | E25: =COUNTIFS(PolicyYears,B25,CurrentDeductible,">0",OwnershipStatus,'Drop downs'!$B$3) -> 0 | F25: =SUMIFS(CurrentDeductible,PolicyYears,B25,OwnershipStatus,'Drop downs'!$B$3) -> 0 | G25: =COUNTIFS(PolicyYears,B25,OtherDeductible,">0",OwnershipStatus,'Drop downs'!$B$3) -> 0 | H25: =SUMIFS(OtherDeductible,PolicyYears,B25,OwnershipStatus,'Drop downs'!$B$3) -> 0
B26: 2019 - 2020 | C26: =COUNTIFS(OwnershipStatus,'Drop downs'!$B$3,PolicyYears,B26) -> 0 | D26: =SUMIFS(Claim_Total,PolicyYears,B26,OwnershipStatus,'Drop downs'!$B$3) -> 0 | E26: =COUNTIFS(PolicyYears,B26,CurrentDeductible,">0",OwnershipStatus,'Drop downs'!$B$3) -> 0 | F26: =SUMIFS(CurrentDeductible,PolicyYears,B26,OwnershipStatus,'Drop downs'!$B$3) -> 0 | G26: =COUNTIFS(PolicyYears,B26,OtherDeductible,">0",OwnershipStatus,'Drop downs'!$B$3) -> 0 | H26: =SUMIFS(OtherDeductible,PolicyYears,B26,OwnershipStatus,'Drop downs'!$B$3) -> 0
B27: 2020 - 2021 | C27: =COUNTIFS(OwnershipStatus,'Drop downs'!$B$3,PolicyYears,B27) -> 0 | D27: =SUMIFS(Claim_Total,PolicyYears,B27,OwnershipStatus,'Drop downs'!$B$3) -> 0 | E27: =COUNTIFS(PolicyYears,B27,CurrentDeductible,">0",OwnershipStatus,'Drop downs'!$B$3) -> 0 | F27: =SUMIFS(CurrentDeductible,PolicyYears,B27,OwnershipStatus,'Drop downs'!$B$3) -> 0 | G27: =COUNTIFS(PolicyYears,B27,OtherDeductible,">0",OwnershipStatus,'Drop downs'!$B$3) -> 0 | H27: =SUMIFS(OtherDeductible,PolicyYears,B27,OwnershipStatus,'Drop downs'!$B$3) -> 0
B28: 2021 - 2022 | C28: =COUNTIFS(OwnershipStatus,'Drop downs'!$B$3,PolicyYears,B28) -> 0 | D28: =SUMIFS(Claim_Total,PolicyYears,B28,OwnershipStatus,'Drop downs'!$B$3) -> 0 | E28: =COUNTIFS(PolicyYears,B28,CurrentDeductible,">0",OwnershipStatus,'Drop downs'!$B$3) -> 0 | F28: =SUMIFS(CurrentDeductible,PolicyYears,B28,OwnershipStatus,'Drop downs'!$B$3) -> 0 | G28: =COUNTIFS(PolicyYears,B28,OtherDeductible,">0",OwnershipStatus,'Drop downs'!$B$3) -> 0 | H28: =SUMIFS(OtherDeductible,PolicyYears,B28,OwnershipStatus,'Drop downs'!$B$3) -> 0
B29: 2022 - 2023 | C29: =COUNTIFS(OwnershipStatus,'Drop downs'!$B$3,PolicyYears,B29) -> 0 | D29: =SUMIFS(Claim_Total,PolicyYears,B29,OwnershipStatus,'Drop downs'!$B$3) -> 0 | E29: =COUNTIFS(PolicyYears,B29,CurrentDeductible,">0",OwnershipStatus,'Drop downs'!$B$3) -> 0 | F29: =SUMIFS(CurrentDeductible,PolicyYears,B29,OwnershipStatus,'Drop downs'!$B$3) -> 0 | G29: =COUNTIFS(PolicyYears,B29,OtherDeductible,">0",OwnershipStatus,'Drop downs'!$B$3) -> 0 | H29: =SUMIFS(OtherDeductible,PolicyYears,B29,OwnershipStatus,'Drop downs'!$B$3) -> 0
B30: 2023 - 2024 | C30: =COUNTIFS(OwnershipStatus,'Drop downs'!$B$3,PolicyYears,B30) -> 0 | D30: =SUMIFS(Claim_Total,PolicyYears,B30,OwnershipStatus,'Drop downs'!$B$3) -> 0 | E30: =COUNTIFS(PolicyYears,B30,CurrentDeductible,">0",OwnershipStatus,'Drop downs'!$B$3) -> 0 | F30: =SUMIFS(CurrentDeductible,PolicyYears,B30,OwnershipStatus,'Drop downs'!$B$3) -> 0 | G30: =COUNTIFS(PolicyYears,B30,OtherDeductible,">0",OwnershipStatus,'Drop downs'!$B$3) -> 0 | H30: =SUMIFS(OtherDeductible,PolicyYears,B30,OwnershipStatus,'Drop downs'!$B$3) -> 0
B31: 2024 - 2025 | C31: =COUNTIFS(OwnershipStatus,'Drop downs'!$B$3,PolicyYears,B31) -> 0 | D31: {=SUMIFS(Claim_Total,PolicyYears,B31,OwnershipStatus,'Drop downs'!$B$3)} -> 0 | E31: =COUNTIFS(PolicyYears,B31,CurrentDeductible,">0",OwnershipStatus,'Drop downs'!$B$3) -> 0 | F31: =SUMIFS(CurrentDeductible,PolicyYears,B31,OwnershipStatus,'Drop downs'!$B$3) -> 0 | G31: =COUNTIFS(PolicyYears,B31,OtherDeductible,">0",OwnershipStatus,'Drop downs'!$B$3) -> 0 | H31: =SUMIFS(OtherDeductible,PolicyYears,B31,OwnershipStatus,'Drop downs'!$B$3) -> 0
B32: Grand Total | C32: =SUM(C25:C31) -> 0 | D32: =SUM(D25:D31) -> 0 | E32: =SUM(E25:E31) -> 0 | F32: =SUM(F25:F31) -> 0 | G32: =SUM(G25:G31) -> 0 | H32: =SUM(H25:H31) -> 0
B33: =COUNTIF(B25:B31,"*")&"-year AAL" -> 7-year AAL | C33: =C32/COUNTIF($B$25:$B$31,"*") -> 0 | D33: =D32/COUNTIF($B$25:$B$31,"*") -> 0 | E33: =E32/COUNTIF($B$25:$B$31,"*") -> 0 | F33: =F32/COUNTIF($B$25:$B$31,"*") -> 0 | G33: =G32/COUNTIF($B$25:$B$31,"*") -> 0 | H33: =H32/COUNTIF($B$25:$B$31,"*") -> 0
B34: ='Drop downs'!G2&"-year AAL" -> 3-year AAL | C34: =AVERAGE(OFFSET(C24,COUNT(C25:C31),0,-'Drop downs'!$G$2)) -> 0 | D34: =AVERAGE(OFFSET(D24,COUNT(D25:D31),0,-'Drop downs'!$G$2)) -> 0 | E34: =AVERAGE(OFFSET(E24,COUNT(E25:E31),0,-'Drop downs'!$G$2)) -> 0 | F34: =AVERAGE(OFFSET(F24,COUNT(F25:F31),0,-'Drop downs'!$G$2)) -> 0 | G34: =AVERAGE(OFFSET(G24,COUNT(G25:G31),0,-'Drop downs'!$G$2)) -> 0 | H34: =AVERAGE(OFFSET(H24,COUNT(H25:H31),0,-'Drop downs'!$G$2)) -> 0
C37: Proposed Deductible
A38: Claims by Cause of Loss (Owned Locations) | B38: Policy Year | C38: Windstorm | D38: Named Windstorm | E38: Flood | F38: All Other Perils (AOP) | G38: Total
B39: Claim Total | C39: =SUMIFS(CurrentDeductible,OwnershipStatus,'Drop downs'!$B$3,Table1[Loss Classification],'Loss Summary Analysis'!$C$38) -> 0 | D39: =SUMIFS(CurrentDeductible,OwnershipStatus,'Drop downs'!$B$3,Table1[Loss Classification],'Loss Summary Analysis'!$D$38) -> 0 | E39: =SUMIFS(CurrentDeductible,OwnershipStatus,'Drop downs'!$B$3,Table1[Loss Classification],'Loss Summary Analysis'!$E$38) -> 0 | F39: =G39-E39-D39-C39 -> 0 | G39: =SUMIFS(CurrentDeductible,OwnershipStatus,'Drop downs'!$B$3) -> 0
B40: % of Total | C40: =C39/$G$39 -> #DIV/0! | D40: =D39/$G$39 -> #DIV/0! | E40: =E39/$G$39 -> #DIV/0! | F40: =F39/$G$39 -> #DIV/0!
B41: =COUNTIF(B12:B16,"*")&"-year AAL" -> 5-year AAL | C41: =C40/COUNTIF($B$25:$B$31,"*") -> #DIV/0! | D41: =D40/COUNTIF($B$25:$B$31,"*") -> #DIV/0! | E41: =E40/COUNTIF($B$25:$B$31,"*") -> #DIV/0! | F41: =F40/COUNTIF($B$25:$B$31,"*") -> #DIV/0! | G41: =G40/COUNTIF($B$25:$B$31,"*") -> 0

Sheet Loss Summary Analysis w. Agg
A1: =IF('Loss Summary Analysis'!A1=ISBLANK(0),"Client Name",'Loss Summary Analysis'!A1) -> Client Name
A2: Property Loss Summary
D4: ='Claim Details'!T7 -> Loss Classification | E4: Proposed Deductible | G4: Alternative Deductible
D5: ='Claim Details'!T8 -> AOP | E5: ='Plus Agg Analysis'!H4 -> 0 | G5: ='Plus Agg Analysis'!H54 -> 0
D6: =IF('Claim Details'!T9=0,"",'Claim Details'!T9) -> Windstorm | E6: ='Plus Agg Analysis'!I4 -> 0 | G6: ='Plus Agg Analysis'!I54 -> 0
D7: =IF('Claim Details'!T10=0,"",'Claim Details'!T10) -> Named Windstorm | E7: ='Plus Agg Analysis'!J4 -> 0 | G7: ='Plus Agg Analysis'!J54 -> 0
D8: Plus Aggregate | E8: ='Plus Agg Analysis'!K4 -> 0 | G8: ='Plus Agg Analysis'!K54 -> 0
C11: Gross Loss | E11: Excess of Proposed Deductible | G11: Excess of Alternative Deductible
A12: All Locations in Loss Runs (Owned & Sold) | B12: Policy Year | C12: # of Claims | D12: Total | E12: # of Claims | F12: Claim Total | G12: # of Claims | H12: Claim Total
B13: 2019 - 2020 | C13: =COUNTIF('Claim Details'!$A$17:$A$506,B13) -> 0 | D13: =SUMIF(PolicyYears,B13,Claim_Total) -> 0 | E13: =COUNTIFS('Plus Agg Analysis'!$A$8:$A$49,B13,'Plus Agg Analysis'!$K$8:$K$49,">0") -> 0 | F13: =SUMIF('Plus Agg Analysis'!$A$8:$A$49,B13,'Plus Agg Analysis'!$K$8:$K$49) -> 0 | G13: =COUNTIFS('Plus Agg Analysis'!$A$58:$A$99,B13,'Plus Agg Analysis'!$K$58:$K$99,">0") -> 0 | H13: =SUMIF('Plus Agg Analysis'!$A$58:$A$99,B13,'Plus Agg Analysis'!$K$58:$K$99) -> 0
B14: 2020 - 2021 | C14: =COUNTIF('Claim Details'!$A$17:$A$506,B14) -> 0 | D14: =SUMIF(PolicyYears,B14,Claim_Total) -> 0 | E14: =COUNTIFS('Plus Agg Analysis'!$A$8:$A$49,B14,'Plus Agg Analysis'!$K$8:$K$49,">0") -> 0 | F14: =SUMIF('Plus Agg Analysis'!$A$8:$A$49,B14,'Plus Agg Analysis'!$K$8:$K$49) -> 0 | G14: =COUNTIFS('Plus Agg Analysis'!$A$58:$A$99,B14,'Plus Agg Analysis'!$K$58:$K$99,">0") -> 0 | H14: =SUMIF('Plus Agg Analysis'!$A$58:$A$99,B14,'Plus Agg Analysis'!$K$58:$K$99) -> 0
B15: 2021 - 2022 | C15: =COUNTIF('Claim Details'!$A$17:$A$506,B15) -> 0 | D15: =SUMIF(PolicyYears,B15,Claim_Total) -> 0 | E15: =COUNTIFS('Plus Agg Analysis'!$A$8:$A$49,B15,'Plus Agg Analysis'!$K$8:$K$49,">0") -> 0 | F15: =SUMIF('Plus Agg Analysis'!$A$8:$A$49,B15,'Plus Agg Analysis'!$K$8:$K$49) -> 0 | G15: =COUNTIFS('Plus Agg Analysis'!$A$58:$A$99,B15,'Plus Agg Analysis'!$K$58:$K$99,">0") -> 0 | H15: =SUMIF('Plus Agg Analysis'!$A$58:$A$99,B15,'Plus Agg Analysis'!$K$58:$K$99) -> 0
B16: 2022 - 2023 | C16: =IF(B16=0,"",COUNTIF(PolicyYears,B16)) -> 0 | D16: =IF(B16=0,"",SUMIF(PolicyYears,B16,Claim_Total)) -> 0 | E16: =COUNTIFS('Plus Agg Analysis'!$A$8:$A$49,B16,'Plus Agg Analysis'!$K$8:$K$49,">0") -> 0 | F16: =SUMIF('Plus Agg Analysis'!$A$8:$A$49,B16,'Plus Agg Analysis'!$K$8:$K$49) -> 0 | G16: =COUNTIFS('Plus Agg Analysis'!$A$58:$A$99,B16,'Plus Agg Analysis'!$K$58:$K$99,">0") -> 0 | H16: =SUMIF('Plus Agg Analysis'!$A$58:$A$99,B16,'Plus Agg Analysis'!$K$58:$K$99) -> 0
B17: 2023 - 2024 | C17: =IF(B17=0,"",COUNTIF(PolicyYears,B17)) -> 0 | D17: =IF(B17=0,"",SUMIF(PolicyYears,B17,Claim_Total)) -> 0 | E17: =COUNTIFS('Plus Agg Analysis'!$A$8:$A$49,B17,'Plus Agg Analysis'!$K$8:$K$49,">0") -> 0 | F17: =SUMIF('Plus Agg Analysis'!$A$8:$A$49,B17,'Plus Agg Analysis'!$K$8:$K$49) -> 0 | G17: =COUNTIFS('Plus Agg Analysis'!$A$58:$A$99,B17,'Plus Agg Analysis'!$K$58:$K$99,">0") -> 0 | H17: =SUMIF('Plus Agg Analysis'!$A$58:$A$99,B17,'Plus Agg Analysis'!$K$58:$K$99) -> 0
B18: Grand Total | C18: =SUM(C13:C17) -> 0 | D18: =SUM(D13:D17) -> 0 | E18: =SUM(E13:E17) -> 0 | F18: =SUM(F13:F17) -> 0 | G18: =SUM(G13:G17) -> 0 | H18: =SUM(H13:H17) -> 0
B19: =COUNTIF(B13:B17,"*")&"-year AAL" -> 5-year AAL | C19: =C18/COUNTIF($B$13:$B$17,"*") -> 0 | D19: =D18/COUNTIF($B$13:$B$17,"*") -> 0 | E19: =E18/COUNTIF($B$13:$B$17,"*") -> 0 | F19: =F18/COUNTIF($B$13:$B$17,"*") -> 0 | G19: =G18/COUNTIF($B$13:$B$17,"*") -> 0 | H19: =H18/COUNTIF($B$13:$B$17,"*") -> 0
B20: ='Drop downs'!G2&"-year AAL" -> 3-year AAL | C20: =AVERAGE(OFFSET(C12,COUNT(C13:C17),0,-'Drop downs'!$G$2)) -> 0 | D20: =AVERAGE(OFFSET(D12,COUNT(D13:D17),0,-'Drop downs'!$G$2)) -> 0 | E20: =AVERAGE(OFFSET(E12,COUNT(E13:E17),0,-'Drop downs'!$G$2)) -> 0 | F20: =AVERAGE(OFFSET(F12,COUNT(F13:F17),0,-'Drop downs'!$G$2)) -> 0 | G20: =AVERAGE(OFFSET(G12,COUNT(G13:G17),0,-'Drop downs'!$G$2)) -> 0 | H20: =AVERAGE(OFFSET(H12,COUNT(H13:H17),0,-'Drop downs'!$G$2)) -> 0
C23: Gross Loss | E23: Excess of Proposed Deductible | G23: Excess of Alternative Deductible
A24: Currently Owned Locations Only | B24: Policy Year | C24: # of Claims | D24: Total | E24: # of Claims | F24: Claim Total | G24: # of Claims | H24: Claim Total
B25: 2018 - 2019 | C25: =COUNTIFS(OwnershipStatus,'Drop downs'!$B$3,PolicyYears,B25) -> 0 | D25: =SUMIFS(Claim_Total,PolicyYears,B25,OwnershipStatus,'Drop downs'!$B$3) -> 0 | E25: =COUNTIFS('Plus Agg Analysis'!$A$8:$A$49,B25,'Plus Agg Analysis'!$K$8:$K$49,">0",'Plus Agg Analysis'!$C$8:$C$49,'Drop downs'!$B$3) -> 0 | F25: =SUMIFS('Plus Agg Analysis'!$K$8:$K$49,'Plus Agg Analysis'!$A$8:$A$49,'Loss Summary Analysis'!B25,'Plus Agg Analysis'!$C$8:$C$49,'Drop downs'!$B$3) -> 0 | G25: =COUNTIFS(PolicyYears,B25,OtherDeductible,">0",OwnershipStatus,'Drop downs'!$B$3) -> 0 | H25: =SUMIFS('Plus Agg Analysis'!$K$58:$K$99,'Plus Agg Analysis'!$A$58:$A$99,'Loss Summary Analysis'!B25,'Plus Agg Analysis'!$C$58:$C$99,'Drop downs'!$B$3) -> 0
B26: 2019 - 2020 | C26: =COUNTIFS(OwnershipStatus,'Drop downs'!$B$3,PolicyYears,B26) -> 0 | D26: =SUMIFS(Claim_Total,PolicyYears,B26,OwnershipStatus,'Drop downs'!$B$3) -> 0 | E26: =COUNTIFS('Plus Agg Analysis'!$A$8:$A$49,B26,'Plus Agg Analysis'!$K$8:$K$49,">0",'Plus Agg Analysis'!$C$8:$C$49,'Drop downs'!$B$3) -> 0 | F26: =SUMIFS('Plus Agg Analysis'!$K$8:$K$49,'Plus Agg Analysis'!$A$8:$A$49,'Loss Summary Analysis'!B27,'Plus Agg Analysis'!$C$8:$C$49,'Drop downs'!$B$3) -> 0 | G26: =COUNTIFS(PolicyYears,B26,OtherDeductible,">0",OwnershipStatus,'Drop downs'!$B$3) -> 0 | H26: =SUMIFS('Plus Agg Analysis'!$K$58:$K$99,'Plus Agg Analysis'!$A$58:$A$99,'Loss Summary Analysis'!B27,'Plus Agg Analysis'!$C$58:$C$99,'Drop downs'!$B$3) -> 0
B27: 2020 - 2021 | C27: =IF(B27=0,"",COUNTIFS(OwnershipStatus,'Drop downs'!$B$3,PolicyYears,B27)) -> 0 | D27: =IF(B27=0,"",SUMIFS(Claim_Total,PolicyYears,B27,OwnershipStatus,'Drop downs'!$B$3)) -> 0 | E27: =COUNTIFS('Plus Agg Analysis'!$A$8:$A$49,B27,'Plus Agg Analysis'!$K$8:$K$49,">0",'Plus Agg Analysis'!$C$8:$C$49,'Drop downs'!$B$3) -> 0 | F27: =SUMIFS('Plus Agg Analysis'!$K$8:$K$49,'Plus Agg Analysis'!$A$8:$A$49,'Loss Summary Analysis'!B28,'Plus Agg Analysis'!$C$8:$C$49,'Drop downs'!$B$3) -> 0 | G27: =IF(B27=0,"",COUNTIFS(PolicyYears,B27,OtherDeductible,">0",OwnershipStatus,'Drop downs'!$B$3)) -> 0 | H27: =SUMIFS('Plus Agg Analysis'!$K$58:$K$99,'Plus Agg Analysis'!$A$58:$A$99,'Loss Summary Analysis'!B28,'Plus Agg Analysis'!$C$58:$C$99,'Drop downs'!$B$3) -> 0
B28: 2021 - 2022 | C28: =IF(B28=0,"",COUNTIFS(OwnershipStatus,'Drop downs'!$B$3,PolicyYears,B28)) -> 0 | D28: =IF(B28=0,"",SUMIFS(Claim_Total,PolicyYears,B28,OwnershipStatus,'Drop downs'!$B$3)) -> 0 | E28: =COUNTIFS('Plus Agg Analysis'!$A$8:$A$49,B28,'Plus Agg Analysis'!$K$8:$K$49,">0",'Plus Agg Analysis'!$C$8:$C$49,'Drop downs'!$B$3) -> 0 | F28: =SUMIFS('Plus Agg Analysis'!$K$8:$K$49,'Plus Agg Analysis'!$A$8:$A$49,'Loss Summary Analysis'!B29,'Plus Agg Analysis'!$C$8:$C$49,'Drop downs'!$B$3) -> 0 | G28: =IF(B28=0,"",COUNTIFS(PolicyYears,B28,OtherDeductible,">0",OwnershipStatus,'Drop downs'!$B$3)) -> 0 | H28: =SUMIFS('Plus Agg Analysis'!$K$58:$K$99,'Plus Agg Analysis'!$A$58:$A$99,'Loss Summary Analysis'!B29,'Plus Agg Analysis'!$C$58:$C$99,'Drop downs'!$B$3) -> 0
B29: 2022 - 2023 | C29: =IF(B29=0,"",COUNTIFS(OwnershipStatus,'Drop downs'!$B$3,PolicyYears,B29)) -> 0 | D29: =IF(B29=0,"",SUMIFS(Claim_Total,PolicyYears,B29,OwnershipStatus,'Drop downs'!$B$3)) -> 0 | E29: =COUNTIFS('Plus Agg Analysis'!$A$8:$A$49,B29,'Plus Agg Analysis'!$K$8:$K$49,">0",'Plus Agg Analysis'!$C$8:$C$49,'Drop downs'!$B$3) -> 0 | F29: =SUMIFS('Plus Agg Analysis'!$K$8:$K$49,'Plus Agg Analysis'!$A$8:$A$49,'Loss Summary Analysis'!B30,'Plus Agg Analysis'!$C$8:$C$49,'Drop downs'!$B$3) -> 0 | G29: =IF(B29=0,"",COUNTIFS(PolicyYears,B29,OtherDeductible,">0",OwnershipStatus,'Drop downs'!$B$3)) -> 0 | H29: =SUMIFS('Plus Agg Analysis'!$K$58:$K$99,'Plus Agg Analysis'!$A$58:$A$99,'Loss Summary Analysis'!B30,'Plus Agg Analysis'!$C$58:$C$99,'Drop downs'!$B$3) -> 0
B30: 2023 - 2024 | C30: =IF(B30=0,"",COUNTIFS(OwnershipStatus,'Drop downs'!$B$3,PolicyYears,B30)) -> 0 | D30: =IF(B30=0,"",SUMIFS(Claim_Total,PolicyYears,B30,OwnershipStatus,'Drop downs'!$B$3)) -> 0 | E30: =COUNTIFS('Plus Agg Analysis'!$A$8:$A$49,B30,'Plus Agg Analysis'!$K$8:$K$49,">0",'Plus Agg Analysis'!$C$8:$C$49,'Drop downs'!$B$3) -> 0 | F30: =SUMIFS('Plus Agg Analysis'!$K$8:$K$49,'Plus Agg Analysis'!$A$8:$A$49,'Loss Summary Analysis'!B31,'Plus Agg Analysis'!$C$8:$C$49,'Drop downs'!$B$3) -> 0 | G30: =IF(B30=0,"",COUNTIFS(PolicyYears,B30,OtherDeductible,">0",OwnershipStatus,'Drop downs'!$B$3)) -> 0 | H30: =SUMIFS('Plus Agg Analysis'!$K$58:$K$99,'Plus Agg Analysis'!$A$58:$A$99,'Loss Summary Analysis'!B31,'Plus Agg Analysis'!$C$58:$C$99,'Drop downs'!$B$3) -> 0
B31: Grand Total | C31: =SUM(C25:C30) -> 0 | D31: =SUM(D25:D30) -> 0 | E31: =SUM(E24:E30) -> 0 | F31: =SUM(F24:F30) -> 0 | G31: =SUM(G24:G30) -> 0 | H31: =SUM(H24:H30) -> 0
B32: =COUNTIF(B25:B30,"*")&"-year AAL" -> 6-year AAL | C32: =C31/COUNTIF($B$25:$B$30,"*") -> 0 | D32: =D31/COUNTIF($B$25:$B$30,"*") -> 0 | E32: =E31/COUNTIF($B$13:$B$17,"*") -> 0 | F32: =F31/COUNTIF($B$13:$B$17,"*") -> 0 | G32: =G31/COUNTIF($B$13:$B$17,"*") -> 0 | H32: =H31/COUNTIF($B$13:$B$17,"*") -> 0
B33: ='Drop downs'!G2&"-year AAL" -> 3-year AAL | C33: =AVERAGE(OFFSET(C24,COUNT(C25:C30),0,-'Drop downs'!$G$2)) -> 0 | D33: =AVERAGE(OFFSET(D24,COUNT(D25:D30),0,-'Drop downs'!$G$2)) -> 0 | E33: =AVERAGE(OFFSET(E24,COUNT(E25:E30),0,-'Drop downs'!$G$2)) -> 0 | F33: =AVERAGE(OFFSET(F24,COUNT(F25:F30),0,-'Drop downs'!$G$2)) -> 0 | G33: =AVERAGE(OFFSET(G24,COUNT(G25:G30),0,-'Drop downs'!$G$2)) -> 0 | H33: =AVERAGE(OFFSET(H24,COUNT(H25:H30),0,-'Drop downs'!$G$2)) -> 0
C36: Proposed Deductible
A37: Claims by Cause of Loss (Owned Locations) | B37: Policy Year | C37: Windstorm | D37: Named Windstorm | E37: Flood | F37: All Other Perils (AOP) | G37: Total
B38: Claim Total | C38: =SUMIF('Plus Agg Analysis'!$D$8:$D$49,'Loss Summary Analysis w. Agg'!$C$37,'Plus Agg Analysis'!$K$8:$K$49) -> 0 | D38: =SUMIF('Plus Agg Analysis'!$D$8:$D$49,'Loss Summary Analysis w. Agg'!$D$37,'Plus Agg Analysis'!$K$8:$K$49) -> 0 | E38: =SUMIF('Plus Agg Analysis'!$D$8:$D$49,'Loss Summary Analysis w. Agg'!$E$37,'Plus Agg Analysis'!$K$8:$K$49) -> 0 | F38: =G38-E38-D38-C38 -> 0 | G38: =SUM('Plus Agg Analysis'!$K$8:$K$49) -> 0
B39: % of Total | C39: =C38/$G$38 -> #DIV/0! | D39: =D38/$G$38 -> #DIV/0! | E39: =E38/$G$38 -> #DIV/0! | F39: =F38/$G$38 -> #DIV/0!
B40: =COUNTIF(B13:B17,"*")&"-year AAL" -> 5-year AAL | C40: =C39/COUNTIF($B$25:$B$30,"*") -> #DIV/0! | D40: =D39/COUNTIF($B$25:$B$30,"*") -> #DIV/0! | E40: =E39/COUNTIF($B$25:$B$30,"*") -> #DIV/0! | F40: =F39/COUNTIF($B$25:$B$30,"*") -> #DIV/0! | G40: =G39/COUNTIF($B$25:$B$30,"*") -> 0

Sheet Plus Agg Analysis
A1: =IF('Loss Summary Analysis'!A1=ISBLANK(0),"Client Name",'Loss Summary Analysis'!A1) -> Client Name
A2: Plus Aggregate Analysis | H2: Deductibles
D3: ONLY EDIT DEDUCTIBLES | H3: All Other Perils | I3: Windstorm | J3: Named Windstorm | K3: Plus Aggregate
A4: Proposed Deductible
A6: Policy Period | B6: Loss Location | C6: Ownership Status | D6: Cause of Loss | E6: Claims Applicable to Aggregate | F6: Claims Not Applicable to Aggregate | H6: Claim Excess of Going in Deductible | I6: Insured Claims Within Plus Agg | J6: Remaining Plus Agg | K6: Adjusted Claim Total Paid by Carrier | M6: Location TIV (For Wind Claims) | N6: Claims Appliclable to agg total | O6: Claims Not applicable to agg total
J7: =K4 -> 0
B8: =IF('Claim Details'!F17=ISBLANK(0),"",'Claim Details'!F17) | C8: =IF('Claim Details'!I17=ISBLANK(0),"",'Claim Details'!I17) | D8: =IF('Claim Details'!K17=ISBLANK(0),"",'Claim Details'!K17) | E8: =IF(LEN(A8)=0,"",IF(OR(D8='Drop downs'!$D$4,D8='Drop downs'!$D$7,D8='Drop downs'!$D$8),0,IF('Claim Details'!Q17=ISBLANK(0),"",'Claim Details'!Q17))) | F8: =IF(LEN(A8)=0,"",IF(OR(D8='Drop downs'!$D$4,D8='Drop downs'!$D$7,D8='Drop downs'!$D$8),IF('Claim Details'!Q17=ISBLANK(0),"",'Claim Details'!Q17),0)) | H8: =IF(LEN(A8)=0,"",IF(D8=$J$3,0,IF(D8=$I$3,IF($I$4>1,IF($I$4<E8,E8-$I$4,0),IF(($I$4*M8)<E8,E8-($I$4*M8),0)),IF($H$4<E8,E8-$H$4,0)))) | I8: =IF(LEN(A8)=0,"",IF(H8=0,0,IF(H8>0+IF(A8=A7,J7,$K$4),IF(A8=A7,J7,$K$4),H8))) | J8: =IF(LEN(A8)=0,"",IF(A8=A7,IF(I8>J7,0,J7-I8),$K$4-I8)) | K8: =IF(LEN(A8)=0,"",SUM(N8:O8)) | M8: =IF('Claim Details'!T17=ISBLANK(0),"",'Claim Details'!T17) | N8: =IF(LEN(A8)=0,"",IF(J8=0,H8-I8,0)) | O8: =IF(LEN(A8)=0,"",IF(D8=$I$3,0,IF(D8=$J$3,IF($J$4>1,IF($J$4<F8,F8-$J$4,0),IF(($J$4*M8)<F8,F8-($J$4*M8),0)),IF($H$4<F8,F8-$H$4,0))))
B9: =IF('Claim Details'!F18=ISBLANK(0),"",'Claim Details'!F18) | C9: =IF('Claim Details'!I18=ISBLANK(0),"",'Claim Details'!I18) | D9: =IF('Claim Details'!K18=ISBLANK(0),"",'Claim Details'!K18) | E9: =IF(LEN(A9)=0,"",IF(OR(D9='Drop downs'!$D$4,D9='Drop downs'!$D$7,D9='Drop downs'!$D$8),0,IF('Claim Details'!Q18=ISBLANK(0),"",'Claim Details'!Q18))) | F9: =IF(LEN(A9)=0,"",IF(OR(D9='Drop downs'!$D$4,D9='Drop downs'!$D$7,D9='Drop downs'!$D$8),IF('Claim Details'!Q18=ISBLANK(0),"",'Claim Details'!Q18),0)) | H9: =IF(LEN(A9)=0,"",IF(D9=$J$3,0,IF(D9=$I$3,IF($I$4>1,IF($I$4<E9,E9-$I$4,0),IF(($I$4*M9)<E9,E9-($I$4*M9),0)),IF($H$4<E9,E9-$H$4,0)))) | I9: =IF(LEN(A9)=0,"",IF(H9=0,0,IF(H9>0+IF(A9=A8,J8,$K$4),IF(A9=A8,J8,$K$4),H9))) | J9: =IF(LEN(A9)=0,"",IF(A9=A8,IF(I9>J8,0,J8-I9),$K$4-I9)) | K9: =IF(LEN(A9)=0,"",SUM(N9:O9)) | M9: =IF('Claim Details'!T18=ISBLANK(0),"",'Claim Details'!T18) | N9: =IF(LEN(A9)=0,"",IF(J9=0,H9-I9,0)) | O9: =IF(LEN(A9)=0,"",IF(D9=$I$3,0,IF(D9=$J$3,IF($J$4>1,IF($J$4<F9,F9-$J$4,0),IF(($J$4*M9)<F9,F9-($J$4*M9),0)),IF($H$4<F9,F9-$H$4,0))))
B10: =IF('Claim Details'!F19=ISBLANK(0),"",'Claim Details'!F19) | C10: =IF('Claim Details'!I19=ISBLANK(0),"",'Claim Details'!I19) | D10: =IF('Claim Details'!K19=ISBLANK(0),"",'Claim Details'!K19) | E10: =IF(LEN(A10)=0,"",IF(OR(D10='Drop downs'!$D$4,D10='Drop downs'!$D$7,D10='Drop downs'!$D$8),0,IF('Claim Details'!Q19=ISBLANK(0),"",'Claim Details'!Q19))) | F10: =IF(LEN(A10)=0,"",IF(OR(D10='Drop downs'!$D$4,D10='Drop downs'!$D$7,D10='Drop downs'!$D$8),IF('Claim Details'!Q19=ISBLANK(0),"",'Claim Details'!Q19),0)) | H10: =IF(LEN(A10)=0,"",IF(D10=$J$3,0,IF(D10=$I$3,IF($I$4>1,IF($I$4<E10,E10-$I$4,0),IF(($I$4*M10)<E10,E10-($I$4*M10),0)),IF($H$4<E10,E10-$H$4,0)))) | I10: =IF(LEN(A10)=0,"",IF(H10=0,0,IF(H10>0+IF(A10=A9,J9,$K$4),IF(A10=A9,J9,$K$4),H10))) | J10: =IF(LEN(A10)=0,"",IF(A10=A9,IF(I10>J9,0,J9-I10),$K$4-I10)) | K10: =IF(LEN(A10)=0,"",SUM(N10:O10)) | M10: =IF('Claim Details'!T19=ISBLANK(0),"",'Claim Details'!T19) | N10: =IF(LEN(A10)=0,"",IF(J10=0,H10-I10,0)) | O10: =IF(LEN(A10)=0,"",IF(D10=$I$3,0,IF(D10=$J$3,IF($J$4>1,IF($J$4<F10,F10-$J$4,0),IF(($J$4*M10)<F10,F10-($J$4*M10),0)),IF($H$4<F10,F10-$H$4,0))))
B11: =IF('Claim Details'!F20=ISBLANK(0),"",'Claim Details'!F20) | C11: =IF('Claim Details'!I20=ISBLANK(0),"",'Claim Details'!I20) | D11: =IF('Claim Details'!K20=ISBLANK(0),"",'Claim Details'!K20) | E11: =IF(LEN(A11)=0,"",IF(OR(D11='Drop downs'!$D$4,D11='Drop downs'!$D$7,D11='Drop downs'!$D$8),0,IF('Claim Details'!Q20=ISBLANK(0),"",'Claim Details'!Q20))) | F11: =IF(LEN(A11)=0,"",IF(OR(D11='Drop downs'!$D$4,D11='Drop downs'!$D$7,D11='Drop downs'!$D$8),IF('Claim Details'!Q20=ISBLANK(0),"",'Claim Details'!Q20),0)) | H11: =IF(LEN(A11)=0,"",IF(D11=$J$3,0,IF(D11=$I$3,IF($I$4>1,IF($I$4<E11,E11-$I$4,0),IF(($I$4*M11)<E11,E11-($I$4*M11),0)),IF($H$4<E11,E11-$H$4,0)))) | I11: =IF(LEN(A11)=0,"",IF(H11=0,0,IF(H11>0+IF(A11=A10,J10,$K$4),IF(A11=A10,J10,$K$4),H11))) | J11: =IF(LEN(A11)=0,"",IF(A11=A10,IF(I11>J10,0,J10-I11),$K$4-I11)) | K11: =IF(LEN(A11)=0,"",SUM(N11:O11)) | M11: =IF('Claim Details'!T20=ISBLANK(0),"",'Claim Details'!T20) | N11: =IF(LEN(A11)=0,"",IF(J11=0,H11-I11,0)) | O11: =IF(LEN(A11)=0,"",IF(D11=$I$3,0,IF(D11=$J$3,IF($J$4>1,IF($J$4<F11,F11-$J$4,0),IF(($J$4*M11)<F11,F11-($J$4*M11),0)),IF($H$4<F11,F11-$H$4,0))))
B12: =IF('Claim Details'!F21=ISBLANK(0),"",'Claim Details'!F21) | C12: =IF('Claim Details'!I21=ISBLANK(0),"",'Claim Details'!I21) | D12: =IF('Claim Details'!K21=ISBLANK(0),"",'Claim Details'!K21) | E12: =IF(LEN(A12)=0,"",IF(OR(D12='Drop downs'!$D$4,D12='Drop downs'!$D$7,D12='Drop downs'!$D$8),0,IF('Claim Details'!Q21=ISBLANK(0),"",'Claim Details'!Q21))) | F12: =IF(LEN(A12)=0,"",IF(OR(D12='Drop downs'!$D$4,D12='Drop downs'!$D$7,D12='Drop downs'!$D$8),IF('Claim Details'!Q21=ISBLANK(0),"",'Claim Details'!Q21),0)) | H12: =IF(LEN(A12)=0,"",IF(D12=$J$3,0,IF(D12=$I$3,IF($I$4>1,IF($I$4<E12,E12-$I$4,0),IF(($I$4*M12)<E12,E12-($I$4*M12),0)),IF($H$4<E12,E12-$H$4,0)))) | I12: =IF(LEN(A12)=0,"",IF(H12=0,0,IF(H12>0+IF(A12=A11,J11,$K$4),IF(A12=A11,J11,$K$4),H12))) | J12: =IF(LEN(A12)=0,"",IF(A12=A11,IF(I12>J11,0,J11-I12),$K$4-I12)) | K12: =IF(LEN(A12)=0,"",SUM(N12:O12)) | M12: =IF('Claim Details'!T21=ISBLANK(0),"",'Claim Details'!T21) | N12: =IF(LEN(A12)=0,"",IF(J12=0,H12-I12,0)) | O12: =IF(LEN(A12)=0,"",IF(D12=$I$3,0,IF(D12=$J$3,IF($J$4>1,IF($J$4<F12,F12-$J$4,0),IF(($J$4*M12)<F12,F12-($J$4*M12),0)),IF($H$4<F12,F12-$H$4,0))))
A13: =IF('Claim Details'!A22=ISBLANK(0),"",'Claim Details'!A22) | B13: =IF('Claim Details'!F22=ISBLANK(0),"",'Claim Details'!F22) | C13: =IF('Claim Details'!I22=ISBLANK(0),"",'Claim Details'!I22) | D13: =IF('Claim Details'!K22=ISBLANK(0),"",'Claim Details'!K22) | E13: =IF(LEN(A13)=0,"",IF(OR(D13='Drop downs'!$D$4,D13='Drop downs'!$D$7,D13='Drop downs'!$D$8),0,IF('Claim Details'!Q22=ISBLANK(0),"",'Claim Details'!Q22))) | F13: =IF(LEN(A13)=0,"",IF(OR(D13='Drop downs'!$D$4,D13='Drop downs'!$D$7,D13='Drop downs'!$D$8),IF('Claim Details'!Q22=ISBLANK(0),"",'Claim Details'!Q22),0)) | H13: =IF(LEN(A13)=0,"",IF(D13=$J$3,0,IF(D13=$I$3,IF($I$4>1,IF($I$4<E13,E13-$I$4,0),IF(($I$4*M13)<E13,E13-($I$4*M13),0)),IF($H$4<E13,E13-$H$4,0)))) | I13: =IF(LEN(A13)=0,"",IF(H13=0,0,IF(H13>0+IF(A13=A12,J12,$K$4),IF(A13=A12,J12,$K$4),H13))) | J13: =IF(LEN(A13)=0,"",IF(A13=A12,IF(I13>J12,0,J12-I13),$K$4-I13)) | K13: =IF(LEN(A13)=0,"",SUM(N13:O13)) | M13: =IF('Claim Details'!T22=ISBLANK(0),"",'Claim Details'!T22) | N13: =IF(LEN(A13)=0,"",IF(J13=0,H13-I13,0)) | O13: =IF(LEN(A13)=0,"",IF(D13=$I$3,0,IF(D13=$J$3,IF($J$4>1,IF($J$4<F13,F13-$J$4,0),IF(($J$4*M13)<F13,F13-($J$4*M13),0)),IF($H$4<F13,F13-$H$4,0))))
A14: =IF('Claim Details'!A23=ISBLANK(0),"",'Claim Details'!A23) | B14: =IF('Claim Details'!F23=ISBLANK(0),"",'Claim Details'!F23) | C14: =IF('Claim Details'!I23=ISBLANK(0),"",'Claim Details'!I23) | D14: =IF('Claim Details'!K23=ISBLANK(0),"",'Claim Details'!K23) | E14: =IF(LEN(A14)=0,"",IF(OR(D14='Drop downs'!$D$4,D14='Drop downs'!$D$7,D14='Drop downs'!$D$8),0,IF('Claim Details'!Q23=ISBLANK(0),"",'Claim Details'!Q23))) | F14: =IF(LEN(A14)=0,"",IF(OR(D14='Drop downs'!$D$4,D14='Drop downs'!$D$7,D14='Drop downs'!$D$8),IF('Claim Details'!Q23=ISBLANK(0),"",'Claim Details'!Q23),0)) | H14: =IF(LEN(A14)=0,"",IF(D14=$J$3,0,IF(D14=$I$3,IF($I$4>1,IF($I$4<E14,E14-$I$4,0),IF(($I$4*M14)<E14,E14-($I$4*M14),0)),IF($H$4<E14,E14-$H$4,0)))) | I14: =IF(LEN(A14)=0,"",IF(H14=0,0,IF(H14>0+IF(A14=A13,J13,$K$4),IF(A14=A13,J13,$K$4),H14))) | J14: =IF(LEN(A14)=0,"",IF(A14=A13,IF(I14>J13,0,J13-I14),$K$4-I14)) | K14: =IF(LEN(A14)=0,"",SUM(N14:O14)) | M14: =IF('Claim Details'!T23=ISBLANK(0),"",'Claim Details'!T23) | N14: =IF(LEN(A14)=0,"",IF(J14=0,H14-I14,0)) | O14: =IF(LEN(A14)=0,"",IF(D14=$I$3,0,IF(D14=$J$3,IF($J$4>1,IF($J$4<F14,F14-$J$4,0),IF(($J$4*M14)<F14,F14-($J$4*M14),0)),IF($H$4<F14,F14-$H$4,0))))
A15: =IF('Claim Details'!A24=ISBLANK(0),"",'Claim Details'!A24) | B15: =IF('Claim Details'!F24=ISBLANK(0),"",'Claim Details'!F24) | C15: =IF('Claim Details'!I24=ISBLANK(0),"",'Claim Details'!I24) | D15: =IF('Claim Details'!K24=ISBLANK(0),"",'Claim Details'!K24) | E15: =IF(LEN(A15)=0,"",IF(OR(D15='Drop downs'!$D$4,D15='Drop downs'!$D$7,D15='Drop downs'!$D$8),0,IF('Claim Details'!Q24=ISBLANK(0),"",'Claim Details'!Q24))) | F15: =IF(LEN(A15)=0,"",IF(OR(D15='Drop downs'!$D$4,D15='Drop downs'!$D$7,D15='Drop downs'!$D$8),IF('Claim Details'!Q24=ISBLANK(0),"",'Claim Details'!Q24),0)) | H15: =IF(LEN(A15)=0,"",IF(D15=$J$3,0,IF(D15=$I$3,IF($I$4>1,IF($I$4<E15,E15-$I$4,0),IF(($I$4*M15)<E15,E15-($I$4*M15),0)),IF($H$4<E15,E15-$H$4,0)))) | I15: =IF(LEN(A15)=0,"",IF(H15=0,0,IF(H15>0+IF(A15=A14,J14,$K$4),IF(A15=A14,J14,$K$4),H15))) | J15: =IF(LEN(A15)=0,"",IF(A15=A14,IF(I15>J14,0,J14-I15),$K$4-I15)) | K15: =IF(LEN(A15)=0,"",SUM(N15:O15)) | M15: =IF('Claim Details'!T24=ISBLANK(0),"",'Claim Details'!T24) | N15: =IF(LEN(A15)=0,"",IF(J15=0,H15-I15,0)) | O15: =IF(LEN(A15)=0,"",IF(D15=$I$3,0,IF(D15=$J$3,IF($J$4>1,IF($J$4<F15,F15-$J$4,0),IF(($J$4*M15)<F15,F15-($J$4*M15),0)),IF($H$4<F15,F15-$H$4,0))))
A16: =IF('Claim Details'!A25=ISBLANK(0),"",'Claim Details'!A25) | B16: =IF('Claim Details'!F25=ISBLANK(0),"",'Claim Details'!F25) | C16: =IF('Claim Details'!I25=ISBLANK(0),"",'Claim Details'!I25) | D16: =IF('Claim Details'!K25=ISBLANK(0),"",'Claim Details'!K25) | E16: =IF(LEN(A16)=0,"",IF(OR(D16='Drop downs'!$D$4,D16='Drop downs'!$D$7,D16='Drop downs'!$D$8),0,IF('Claim Details'!Q25=ISBLANK(0),"",'Claim Details'!Q25))) | F16: =IF(LEN(A16)=0,"",IF(OR(D16='Drop downs'!$D$4,D16='Drop downs'!$D$7,D16='Drop downs'!$D$8),IF('Claim Details'!Q25=ISBLANK(0),"",'Claim Details'!Q25),0)) | H16: =IF(LEN(A16)=0,"",IF(D16=$J$3,0,IF(D16=$I$3,IF($I$4>1,IF($I$4<E16,E16-$I$4,0),IF(($I$4*M16)<E16,E16-($I$4*M16),0)),IF($H$4<E16,E16-$H$4,0)))) | I16: =IF(LEN(A16)=0,"",IF(H16=0,0,IF(H16>0+IF(A16=A15,J15,$K$4),IF(A16=A15,J15,$K$4),H16))) | J16: =IF(LEN(A16)=0,"",IF(A16=A15,IF(I16>J15,0,J15-I16),$K$4-I16)) | K16: =IF(LEN(A16)=0,"",SUM(N16:O16)) | M16: =IF('Claim Details'!T25=ISBLANK(0),"",'Claim Details'!T25) | N16: =IF(LEN(A16)=0,"",IF(J16=0,H16-I16,0)) | O16: =IF(LEN(A16)=0,"",IF(D16=$I$3,0,IF(D16=$J$3,IF($J$4>1,IF($J$4<F16,F16-$J$4,0),IF(($J$4*M16)<F16,F16-($J$4*M16),0)),IF($H$4<F16,F16-$H$4,0))))
A17: =IF('Claim Details'!A26=ISBLANK(0),"",'Claim Details'!A26) | B17: =IF('Claim Details'!F26=ISBLANK(0),"",'Claim Details'!F26) | C17: =IF('Claim Details'!I26=ISBLANK(0),"",'Claim Details'!I26) | D17: =IF('Claim Details'!K26=ISBLANK(0),"",'Claim Details'!K26) | E17: =IF(LEN(A17)=0,"",IF(OR(D17='Drop downs'!$D$4,D17='Drop downs'!$D$7,D17='Drop downs'!$D$8),0,IF('Claim Details'!Q26=ISBLANK(0),"",'Claim Details'!Q26))) | F17: =IF(LEN(A17)=0,"",IF(OR(D17='Drop downs'!$D$4,D17='Drop downs'!$D$7,D17='Drop downs'!$D$8),IF('Claim Details'!Q26=ISBLANK(0),"",'Claim Details'!Q26),0)) | H17: =IF(LEN(A17)=0,"",IF(D17=$J$3,0,IF(D17=$I$3,IF($I$4>1,IF($I$4<E17,E17-$I$4,0),IF(($I$4*M17)<E17,E17-($I$4*M17),0)),IF($H$4<E17,E17-$H$4,0)))) | I17: =IF(LEN(A17)=0,"",IF(H17=0,0,IF(H17>0+IF(A17=A16,J16,$K$4),IF(A17=A16,J16,$K$4),H17))) | J17: =IF(LEN(A17)=0,"",IF(A17=A16,IF(I17>J16,0,J16-I17),$K$4-I17)) | K17: =IF(LEN(A17)=0,"",SUM(N17:O17)) | M17: =IF('Claim Details'!T26=ISBLANK(0),"",'Claim Details'!T26) | N17: =IF(LEN(A17)=0,"",IF(J17=0,H17-I17,0)) | O17: =IF(LEN(A17)=0,"",IF(D17=$I$3,0,IF(D17=$J$3,IF($J$4>1,IF($J$4<F17,F17-$J$4,0),IF(($J$4*M17)<F17,F17-($J$4*M17),0)),IF($H$4<F17,F17-$H$4,0))))
A18: =IF('Claim Details'!A27=ISBLANK(0),"",'Claim Details'!A27) | B18: =IF('Claim Details'!F27=ISBLANK(0),"",'Claim Details'!F27) | C18: =IF('Claim Details'!I27=ISBLANK(0),"",'Claim Details'!I27) | D18: =IF('Claim Details'!K27=ISBLANK(0),"",'Claim Details'!K27) | E18: =IF(LEN(A18)=0,"",IF(OR(D18='Drop downs'!$D$4,D18='Drop downs'!$D$7,D18='Drop downs'!$D$8),0,IF('Claim Details'!Q27=ISBLANK(0),"",'Claim Details'!Q27))) | F18: =IF(LEN(A18)=0,"",IF(OR(D18='Drop downs'!$D$4,D18='Drop downs'!$D$7,D18='Drop downs'!$D$8),IF('Claim Details'!Q27=ISBLANK(0),"",'Claim Details'!Q27),0)) | H18: =IF(LEN(A18)=0,"",IF(D18=$J$3,0,IF(D18=$I$3,IF($I$4>1,IF($I$4<E18,E18-$I$4,0),IF(($I$4*M18)<E18,E18-($I$4*M18),0)),IF($H$4<E18,E18-$H$4,0)))) | I18: =IF(LEN(A18)=0,"",IF(H18=0,0,IF(H18>0+IF(A18=A17,J17,$K$4),IF(A18=A17,J17,$K$4),H18))) | J18: =IF(LEN(A18)=0,"",IF(A18=A17,IF(I18>J17,0,J17-I18),$K$4-I18)) | K18: =IF(LEN(A18)=0,"",SUM(N18:O18)) | M18: =IF('Claim Details'!T27=ISBLANK(0),"",'Claim Details'!T27) | N18: =IF(LEN(A18)=0,"",IF(J18=0,H18-I18,0)) | O18: =IF(LEN(A18)=0,"",IF(D18=$I$3,0,IF(D18=$J$3,IF($J$4>1,IF($J$4<F18,F18-$J$4,0),IF(($J$4*M18)<F18,F18-($J$4*M18),0)),IF($H$4<F18,F18-$H$4,0))))
A19: =IF('Claim Details'!A28=ISBLANK(0),"",'Claim Details'!A28) | B19: =IF('Claim Details'!F28=ISBLANK(0),"",'Claim Details'!F28) | C19: =IF('Claim Details'!I28=ISBLANK(0),"",'Claim Details'!I28) | D19: =IF('Claim Details'!K28=ISBLANK(0),"",'Claim Details'!K28) | E19: =IF(LEN(A19)=0,"",IF(OR(D19='Drop downs'!$D$4,D19='Drop downs'!$D$7,D19='Drop downs'!$D$8),0,IF('Claim Details'!Q28=ISBLANK(0),"",'Claim Details'!Q28))) | F19: =IF(LEN(A19)=0,"",IF(OR(D19='Drop downs'!$D$4,D19='Drop downs'!$D$7,D19='Drop downs'!$D$8),IF('Claim Details'!Q28=ISBLANK(0),"",'Claim Details'!Q28),0)) | H19: =IF(LEN(A19)=0,"",IF(D19=$J$3,0,IF(D19=$I$3,IF($I$4>1,IF($I$4<E19,E19-$I$4,0),IF(($I$4*M19)<E19,E19-($I$4*M19),0)),IF($H$4<E19,E19-$H$4,0)))) | I19: =IF(LEN(A19)=0,"",IF(H19=0,0,IF(H19>0+IF(A19=A18,J18,$K$4),IF(A19=A18,J18,$K$4),H19))) | J19: =IF(LEN(A19)=0,"",IF(A19=A18,IF(I19>J18,0,J18-I19),$K$4-I19)) | K19: =IF(LEN(A19)=0,"",SUM(N19:O19)) | M19: =IF('Claim Details'!T28=ISBLANK(0),"",'Claim Details'!T28) | N19: =IF(LEN(A19)=0,"",IF(J19=0,H19-I19,0)) | O19: =IF(LEN(A19)=0,"",IF(D19=$I$3,0,IF(D19=$J$3,IF($J$4>1,IF($J$4<F19,F19-$J$4,0),IF(($J$4*M19)<F19,F19-($J$4*M19),0)),IF($H$4<F19,F19-$H$4,0))))
A20: =IF('Claim Details'!A29=ISBLANK(0),"",'Claim Details'!A29) | B20: =IF('Claim Details'!F29=ISBLANK(0),"",'Claim Details'!F29) | C20: =IF('Claim Details'!I29=ISBLANK(0),"",'Claim Details'!I29) | D20: =IF('Claim Details'!K29=ISBLANK(0),"",'Claim Details'!K29) | E20: =IF(LEN(A20)=0,"",IF(OR(D20='Drop downs'!$D$4,D20='Drop downs'!$D$7,D20='Drop downs'!$D$8),0,IF('Claim Details'!Q29=ISBLANK(0),"",'Claim Details'!Q29))) | F20: =IF(LEN(A20)=0,"",IF(OR(D20='Drop downs'!$D$4,D20='Drop downs'!$D$7,D20='Drop downs'!$D$8),IF('Claim Details'!Q29=ISBLANK(0),"",'Claim Details'!Q29),0)) | H20: =IF(LEN(A20)=0,"",IF(D20=$J$3,0,IF(D20=$I$3,IF($I$4>1,IF($I$4<E20,E20-$I$4,0),IF(($I$4*M20)<E20,E20-($I$4*M20),0)),IF($H$4<E20,E20-$H$4,0)))) | I20: =IF(LEN(A20)=0,"",IF(H20=0,0,IF(H20>0+IF(A20=A19,J19,$K$4),IF(A20=A19,J19,$K$4),H20))) | J20: =IF(LEN(A20)=0,"",IF(A20=A19,IF(I20>J19,0,J19-I20),$K$4-I20)) | K20: =IF(LEN(A20)=0,"",SUM(N20:O20)) | M20: =IF('Claim Details'!T29=ISBLANK(0),"",'Claim Details'!T29) | N20: =IF(LEN(A20)=0,"",IF(J20=0,H20-I20,0)) | O20: =IF(LEN(A20)=0,"",IF(D20=$I$3,0,IF(D20=$J$3,IF($J$4>1,IF($J$4<F20,F20-$J$4,0),IF(($J$4*M20)<F20,F20-($J$4*M20),0)),IF($H$4<F20,F20-$H$4,0))))
A21: =IF('Claim Details'!A30=ISBLANK(0),"",'Claim Details'!A30) | B21: =IF('Claim Details'!F30=ISBLANK(0),"",'Claim Details'!F30) | C21: =IF('Claim Details'!I30=ISBLANK(0),"",'Claim Details'!I30) | D21: =IF('Claim Details'!K30=ISBLANK(0),"",'Claim Details'!K30) | E21: =IF(LEN(A21)=0,"",IF(OR(D21='Drop downs'!$D$4,D21='Drop downs'!$D$7,D21='Drop downs'!$D$8),0,IF('Claim Details'!Q30=ISBLANK(0),"",'Claim Details'!Q30))) | F21: =IF(LEN(A21)=0,"",IF(OR(D21='Drop downs'!$D$4,D21='Drop downs'!$D$7,D21='Drop downs'!$D$8),IF('Claim Details'!Q30=ISBLANK(0),"",'Claim Details'!Q30),0)) | H21: =IF(LEN(A21)=0,"",IF(D21=$J$3,0,IF(D21=$I$3,IF($I$4>1,IF($I$4<E21,E21-$I$4,0),IF(($I$4*M21)<E21,E21-($I$4*M21),0)),IF($H$4<E21,E21-$H$4,0)))) | I21: =IF(LEN(A21)=0,"",IF(H21=0,0,IF(H21>0+IF(A21=A20,J20,$K$4),IF(A21=A20,J20,$K$4),H21))) | J21: =IF(LEN(A21)=0,"",IF(A21=A20,IF(I21>J20,0,J20-I21),$K$4-I21)) | K21: =IF(LEN(A21)=0,"",SUM(N21:O21)) | M21: =IF('Claim Details'!T30=ISBLANK(0),"",'Claim Details'!T30) | N21: =IF(LEN(A21)=0,"",IF(J21=0,H21-I21,0)) | O21: =IF(LEN(A21)=0,"",IF(D21=$I$3,0,IF(D21=$J$3,IF($J$4>1,IF($J$4<F21,F21-$J$4,0),IF(($J$4*M21)<F21,F21-($J$4*M21),0)),IF($H$4<F21,F21-$H$4,0))))
A22: =IF('Claim Details'!A31=ISBLANK(0),"",'Claim Details'!A31) | B22: =IF('Claim Details'!F31=ISBLANK(0),"",'Claim Details'!F31) | C22: =IF('Claim Details'!I31=ISBLANK(0),"",'Claim Details'!I31) | D22: =IF('Claim Details'!K31=ISBLANK(0),"",'Claim Details'!K31) | E22: =IF(LEN(A22)=0,"",IF(OR(D22='Drop downs'!$D$4,D22='Drop downs'!$D$7,D22='Drop downs'!$D$8),0,IF('Claim Details'!Q31=ISBLANK(0),"",'Claim Details'!Q31))) | F22: =IF(LEN(A22)=0,"",IF(OR(D22='Drop downs'!$D$4,D22='Drop downs'!$D$7,D22='Drop downs'!$D$8),IF('Claim Details'!Q31=ISBLANK(0),"",'Claim Details'!Q31),0)) | H22: =IF(LEN(A22)=0,"",IF(D22=$J$3,0,IF(D22=$I$3,IF($I$4>1,IF($I$4<E22,E22-$I$4,0),IF(($I$4*M22)<E22,E22-($I$4*M22),0)),IF($H$4<E22,E22-$H$4,0)))) | I22: =IF(LEN(A22)=0,"",IF(H22=0,0,IF(H22>0+IF(A22=A21,J21,$K$4),IF(A22=A21,J21,$K$4),H22))) | J22: =IF(LEN(A22)=0,"",IF(A22=A21,IF(I22>J21,0,J21-I22),$K$4-I22)) | K22: =IF(LEN(A22)=0,"",SUM(N22:O22)) | M22: =IF('Claim Details'!T31=ISBLANK(0),"",'Claim Details'!T31) | N22: =IF(LEN(A22)=0,"",IF(J22=0,H22-I22,0)) | O22: =IF(LEN(A22)=0,"",IF(D22=$I$3,0,IF(D22=$J$3,IF($J$4>1,IF($J$4<F22,F22-$J$4,0),IF(($J$4*M22)<F22,F22-($J$4*M22),0)),IF($H$4<F22,F22-$H$4,0))))
A23: =IF('Claim Details'!A32=ISBLANK(0),"",'Claim Details'!A32) | B23: =IF('Claim Details'!F32=ISBLANK(0),"",'Claim Details'!F32) | C23: =IF('Claim Details'!I32=ISBLANK(0),"",'Claim Details'!I32) | D23: =IF('Claim Details'!K32=ISBLANK(0),"",'Claim Details'!K32) | E23: =IF(LEN(A23)=0,"",IF(OR(D23='Drop downs'!$D$4,D23='Drop downs'!$D$7,D23='Drop downs'!$D$8),0,IF('Claim Details'!Q32=ISBLANK(0),"",'Claim Details'!Q32))) | F23: =IF(LEN(A23)=0,"",IF(OR(D23='Drop downs'!$D$4,D23='Drop downs'!$D$7,D23='Drop downs'!$D$8),IF('Claim Details'!Q32=ISBLANK(0),"",'Claim Details'!Q32),0)) | H23: =IF(LEN(A23)=0,"",IF(D23=$J$3,0,IF(D23=$I$3,IF($I$4>1,IF($I$4<E23,E23-$I$4,0),IF(($I$4*M23)<E23,E23-($I$4*M23),0)),IF($H$4<E23,E23-$H$4,0)))) | I23: =IF(LEN(A23)=0,"",IF(H23=0,0,IF(H23>0+IF(A23=A22,J22,$K$4),IF(A23=A22,J22,$K$4),H23))) | J23: =IF(LEN(A23)=0,"",IF(A23=A22,IF(I23>J22,0,J22-I23),$K$4-I23)) | K23: =IF(LEN(A23)=0,"",SUM(N23:O23)) | M23: =IF('Claim Details'!T32=ISBLANK(0),"",'Claim Details'!T32) | N23: =IF(LEN(A23)=0,"",IF(J23=0,H23-I23,0)) | O23: =IF(LEN(A23)=0,"",IF(D23=$I$3,0,IF(D23=$J$3,IF($J$4>1,IF($J$4<F23,F23-$J$4,0),IF(($J$4*M23)<F23,F23-($J$4*M23),0)),IF($H$4<F23,F23-$H$4,0))))
A24: =IF('Claim Details'!A33=ISBLANK(0),"",'Claim Details'!A33) | B24: =IF('Claim Details'!F33=ISBLANK(0),"",'Claim Details'!F33) | C24: =IF('Claim Details'!I33=ISBLANK(0),"",'Claim Details'!I33) | D24: =IF('Claim Details'!K33=ISBLANK(0),"",'Claim Details'!K33) | E24: =IF(LEN(A24)=0,"",IF(OR(D24='Drop downs'!$D$4,D24='Drop downs'!$D$7,D24='Drop downs'!$D$8),0,IF('Claim Details'!Q33=ISBLANK(0),"",'Claim Details'!Q33))) | F24: =IF(LEN(A24)=0,"",IF(OR(D24='Drop downs'!$D$4,D24='Drop downs'!$D$7,D24='Drop downs'!$D$8),IF('Claim Details'!Q33=ISBLANK(0),"",'Claim Details'!Q33),0)) | H24: =IF(LEN(A24)=0,"",IF(D24=$J$3,0,IF(D24=$I$3,IF($I$4>1,IF($I$4<E24,E24-$I$4,0),IF(($I$4*M24)<E24,E24-($I$4*M24),0)),IF($H$4<E24,E24-$H$4,0)))) | I24: =IF(LEN(A24)=0,"",IF(H24=0,0,IF(H24>0+IF(A24=A23,J23,$K$4),IF(A24=A23,J23,$K$4),H24))) | J24: =IF(LEN(A24)=0,"",IF(A24=A23,IF(I24>J23,0,J23-I24),$K$4-I24)) | K24: =IF(LEN(A24)=0,"",SUM(N24:O24)) | M24: =IF('Claim Details'!T33=ISBLANK(0),"",'Claim Details'!T33) | N24: =IF(LEN(A24)=0,"",IF(J24=0,H24-I24,0)) | O24: =IF(LEN(A24)=0,"",IF(D24=$I$3,0,IF(D24=$J$3,IF($J$4>1,IF($J$4<F24,F24-$J$4,0),IF(($J$4*M24)<F24,F24-($J$4*M24),0)),IF($H$4<F24,F24-$H$4,0))))
... A49: =IF('Claim Details'!A58=ISBLANK(0),"",'Claim Details'!A58) | B49: =IF('Claim Details'!F58=ISBLANK(0),"",'Claim Details'!F58) | C49: =IF('Claim Details'!I58=ISBLANK(0),"",'Claim Details'!I58) | D49: =IF('Claim Details'!K58=ISBLANK(0),"",'Claim Details'!K58) | E49: =IF(LEN(A49)=0,"",IF(OR(D49='Drop downs'!$D$4,D49='Drop downs'!$D$7,D49='Drop downs'!$D$8),0,IF('Claim Details'!Q58=ISBLANK(0),"",'Claim Details'!Q58))) | F49: =IF(LEN(A49)=0,"",IF(OR(D49='Drop downs'!$D$4,D49='Drop downs'!$D$7,D49='Drop downs'!$D$8),IF('Claim Details'!Q58=ISBLANK(0),"",'Claim Details'!Q58),0)) | H49: =IF(LEN(A49)=0,"",IF(D49=$J$3,0,IF(D49=$I$3,IF($I$4>1,IF($I$4<E49,E49-$I$4,0),IF(($I$4*M49)<E49,E49-($I$4*M49),0)),IF($H$4<E49,E49-$H$4,0)))) | I49: =IF(LEN(A49)=0,"",IF(H49=0,0,IF(H49>0+IF(A49=A48,J48,$K$4),IF(A49=A48,J48,$K$4),H49))) | J49: =IF(LEN(A49)=0,"",IF(A49=A48,IF(I49>J48,0,J48-I49),$K$4-I49)) | K49: =IF(LEN(A49)=0,"",SUM(N49:O49)) | M49: =IF('Claim Details'!T58=ISBLANK(0),"",'Claim Details'!T58) | N49: =IF(LEN(A49)=0,"",IF(J49=0,H49-I49,0)) | O49: =IF(LEN(A49)=0,"",IF(D49=$I$3,0,IF(D49=$J$3,IF($J$4>1,IF($J$4<F49,F49-$J$4,0),IF(($J$4*M49)<F49,F49-($J$4*M49),0)),IF($H$4<F49,F49-$H$4,0))))
E50: =SUM(E8:E49) -> 0 | F50: =SUM(F8:F49) -> 0 | H50: =SUM(H8:H49) -> 0 | I50: =SUM(I8:I49) -> 0 | K50: =SUM(K8:K49) -> 0 | N50: =SUM(N8:N49) -> 0 | O50: =SUM(O8:O49) -> 0
H52: Deductibles
H53: All Other Perils | I53: Windstorm | J53: Named Windstorm | K53: Plus Aggregate
A54: Alternative Deductible
A56: Policy Period | B56: Loss Location | C56: Ownership Status | D56: Cause of Loss | E56: Claims Applicable to Aggregate | F56: Claims Not Applicable to Aggregate | H56: Claim Excess of Going in Deductible | I56: Insured Claims Within Plus Agg | J56: Remaining Plus Agg | K56: Adjusted Claim Total Paid by Carrier | M56: Location TIV (For Wind Claims) | N56: Claims Appliclable to agg total | O56: Claims Not applicable to agg total
J57: =K54 -> 0
A58: =IF('Claim Details'!A17=ISBLANK(0),"",'Claim Details'!A17) | B58: =IF('Claim Details'!F17=ISBLANK(0),"",'Claim Details'!F17) | C58: =IF('Claim Details'!I17=ISBLANK(0),"",'Claim Details'!I17) | D58: =IF('Claim Details'!K17=ISBLANK(0),"",'Claim Details'!K17) | E58: =IF(LEN(A58)=0,"",IF(OR(D58=$J$53,D58='Drop downs'!$D$7,D58='Drop downs'!$D$8),0,IF('Claim Details'!Q17=ISBLANK(0),"",'Claim Details'!Q17))) | F58: =IF(LEN(A58)=0,"",IF(OR(D58='Drop downs'!$D$4,D58='Drop downs'!$D$7,D58='Drop downs'!$D$8),IF('Claim Details'!Q17=ISBLANK(0),"",'Claim Details'!Q17),0)) | H58: =IF(LEN(A58)=0,"",IF(D58=$J$53,0,IF(D58=$I$53,IF($I$54>1,IF($I$54<E58,E58-$I$54,0),IF(($I$54*M58)<E58,E58-($I$54*M58),0)),IF($H$54<E58,E58-$H$54,0)))) | I58: =IF(LEN(A58)=0,"",IF(E58<$H$54,0,IF(E58>$H$54+IF(A58=A57,J57,$K$54),IF(A58=A57,J57,$K$54),H58))) | J58: =IF(LEN(A58)=0,"",IF(A58=A57,IF(I58>J57,0,J57-I58),$K$54-I58)) | K58: =IF(LEN(A58)=0,"",SUM(N58:O58)) | M58: =IF('Claim Details'!T17=ISBLANK(0),"",'Claim Details'!T17) | N58: =IF(LEN(A58)=0,"",IF(J58=0,H58-I58,0)) | O58: =IF(LEN(A58)=0,"",IF(D58=$I$53,0,IF(D58=$J$53,IF($J$54>1,IF($J$54<F58,F58-$J$54,0),IF(($J$54*M58)<F58,F58-($J$54*M58),0)),IF($H$54<F58,F58-$H$54,0))))
